Workbook

Sheet 1_Kamlesh_Panchal
A1: MINI PROJECT EXHIBITION 2026 | Dynamic System Modeling (702MH0C023) | B.Tech Mechatronics Engineering, Semester IV, AY 2025-26 | NMIMS MPSTME
A2: EVALUATOR: Mr. Kamlesh Panchal ROLE: Industry & Manufacturing Expert
A3: Session: MORNING SESSION | 09:00 AM to 01:00 PM Date: 25 April 2026 (Saturday) Venue: AR/VR Lab, MPSTME, NMIMS
A4: ASSESSMENT FOCUS: Manufacturing viability, scalability, and real-world industry relevance of the mechatronic systems modeled by students.
A5: SF-PBL: Assess whether the mathematical model and simulation can inform real manufacturing and engineering decisions for each system.
A6: CRITERIA KEY: C1: System Buildability | C2: Scalability & Real-World Fit | C3: Engineering Accuracy | C4: Individual Technical Q&A
A7: Roll No. | B7: Student Name | C7: C1 /4 | D7: C2 /4 | E7: C3 /4 | F7: C4 /4 | G7: Total /16 | H7: Comments / Feedback
A8: Group 1 | Mathematical Modeling and Dynamic Analysis of a Multi-Terrain Four-Wheeled Robot
A9: H079 | B9: Student | C9: 3 | D9: 4 | E9: 3 | F9: 4 | G9: =SUM(C9:F9) | H9: Good effort, but room for refinement.
A10: H082 | B10: Student | C10: 4 | D10: 4 | E10: 4 | F10: 4 | G10: =SUM(C10:F10) | H10: Excellent work! Clear and well-presented.
A11: H084 | B11: Student | C11: 3 | D11: 4 | E11: 3 | F11: 4 | G11: =SUM(C11:F11) | H11: Good effort, but room for refinement.
A12: Group 2 | Modeling Rocket Landing - Docking
A13: H004 | B13: Student | C13: 3 | D13: 3 | E13: 4 | F13: 4 | G13: =SUM(C13:F13) | H13: Good effort, but room for refinement.
A14: H005 | B14: Student | C14: 0 | D14: 0 | E14: 0 | F14: 0 | G14: =SUM(C14:F14) | H14: Absent throughout.
A15: H028 | B15: Student | C15: 4 | D15: 3 | E15: 4 | F15: 3 | G15: =SUM(C15:F15) | H15: Good effort, but room for refinement.
A16: H031 | B16: Student | C16: 4 | D16: 3 | E16: 3 | F16: 4 | G16: =SUM(C16:F16) | H16: Good effort, but room for refinement.
A17: Group 3 | Dynamic Modeling and Stability Analysis of 2-DOF Leg Mechanism for Quadruped Robot
A18: H009 | B18: Student | C18: 4 | D18: 4 | E18: 3 | F18: 4 | G18: =SUM(C18:F18) | H18: Good effort, but room for refinement.
A19: H012 | B19: Student | C19: 3 | D19: 4 | E19: 3 | F19: 4 | G19: =SUM(C19:F19) | H19: Good effort, but room for refinement.
A20: H033 | B20: Student | C20: 3 | D20: 3 | E20: 4 | F20: 4 | G20: =SUM(C20:F20) | H20: Good effort, but room for refinement.
A21: Group 4 | Critical Skid Velocity Mathematical Modeling
A22: H014 | B22: Student | C22: 3 | D22: 3 | E22: 1 | F22: 4 | G22: =SUM(C22:F22) | H22: Missing key simulation/validation components.
A23: H015 | B23: Student | C23: 3 | D23: 3 | E23: 1 | F23: 4 | G23: =SUM(C23:F23) | H23: Missing key simulation/validation components.
A24: H016 | B24: Student | C24: 3 | D24: 3 | E24: 1 | F24: 4 | G24: =SUM(C24:F24) | H24: Missing key simulation/validation components.
A25: H025 | B25: Student | C25: 4 | D25: 4 | E25: 1 | F25: 4 | G25: =SUM(C25:F25) | H25: Missing key simulation/validation components.
A26: Group 5 | Humanoid Robot - Dynamic Modeling
A27: H003 | B27: Student | C27: 3 | D27: 4 | E27: 3 | F27: 4 | G27: =SUM(C27:F27) | H27: Good effort, but room for refinement.
A28: H006 | B28: Student | C28: 4 | D28: 4 | E28: 3 | F28: 3 | G28: =SUM(C28:F28) | H28: Good effort, but room for refinement.
A29: H024 | B29: Student | C29: 3 | D29: 4 | E29: 4 | F29: 4 | G29: =SUM(C29:F29) | H29: Good effort, but room for refinement.
A30: H029 | B30: Student | C30: 4 | D30: 3 | E30: 4 | F30: 4 | G30: =SUM(C30:F30) | H30: Good effort, but room for refinement.
A31: Group 6 | Dynamic Modeling of Hydrogen Fuel Cell-Battery Hybrid Powertrain for Electric UAV
A32: H001 | B32: Student | C32: 3 | D32: 3 | E32: 1 | F32: 4 | G32: =SUM(C32:F32) | H32: Missing key simulation/validation components.
A33: H002 | B33: Student | C33: 4 | D33: 3 | E33: 1 | F33: 3 | G33: =SUM(C33:F33) | H33: Missing key simulation/validation components.
A34: Group 7 | Hexapod Robot - Mathematical Modeling
A35: H021 | B35: Student | C35: 4 | D35: 4 | E35: 3 | F35: 4 | G35: =SUM(C35:F35) | H35: Good effort, but room for refinement.
A36: H022 | B36: Student | C36: 4 | D36: 3 | E36: 3 | F36: 3 | G36: =SUM(C36:F36) | H36: Good effort, but room for refinement.
A37: H023 | B37: Student | C37: 3 | D37: 3 | E37: 3 | F37: 4 | G37: =SUM(C37:F37) | H37: Good effort, but room for refinement.
A38: Group 8 | Mathematical Modeling and Dynamics of Ball Balancing Robot using 6-DOF Stewart Mechanism
A39: H059 | B39: Student | C39: 4 | D39: 3 | E39: 4 | F39: 4 | G39: =SUM(C39:F39) | H39: Good effort, but room for refinement.
A40: H060 | B40: Student | C40: 4 | D40: 4 | E40: 4 | F40: 3 | G40: =SUM(C40:F40) | H40: Excellent work! Clear and well-presented.
...

Sheet 2_Hasti_Chandarana
A1: MINI PROJECT EXHIBITION 2026 | Dynamic System Modeling (702MH0C023) | B.Tech Mechatronics Engineering, Semester IV, AY 2025-26 | NMIMS MPSTME
A2: EVALUATOR: Ms. Hasti Chandarana ROLE: Intellectual Property (IP) Expert
A3: Session: MORNING SESSION | 09:00 AM to 01:00 PM Date: 25 April 2026 (Saturday) Venue: AR/VR Lab, MPSTME, NMIMS
A4: ASSESSMENT FOCUS: Novelty, IP potential, and commercial applicability of the project concept and the mathematical modeling approach.
A5: SF-PBL: A novel first-principles derivation may itself constitute an IP element — assess novelty of both the system choice and the mathematical formulation.
A6: CRITERIA KEY: C1: Conceptual Novelty | C2: IP Potential | C3: Commercial Viability | C4: Individual IP Awareness
A7: Roll No. | B7: Student Name | C7: C1 /4 | D7: C2 /4 | E7: C3 /4 | F7: C4 /4 | G7: Total /16 | H7: Comments / Feedback
A8: Group 1 | Mathematical Modeling and Dynamic Analysis of a Multi-Terrain Four-Wheeled Robot
A9: H079 | B9: Student | C9: 3 | D9: 4 | E9: 3 | F9: 4 | G9: =SUM(C9:F9) | H9: Good effort, but room for refinement.
A10: H082 | B10: Student | C10: 4 | D10: 3 | E10: 4 | F10: 4 | G10: =SUM(C10:F10) | H10: Good effort, but room for refinement.
A11: H084 | B11: Student | C11: 3 | D11: 3 | E11: 4 | F11: 4 | G11: =SUM(C11:F11) | H11: Good effort, but room for refinement.
A12: Group 2 | Modeling Rocket Landing - Docking
A13: H004 | B13: Student | C13: 1 | D13: 1 | E13: 4 | F13: 4 | G13: =SUM(C13:F13) | H13: Needs significant improvement. Deliverables missing.
A14: H005 | B14: Student | C14: 0 | D14: 0 | E14: 0 | F14: 0 | G14: =SUM(C14:F14) | H14: Absent throughout.
A15: H028 | B15: Student | C15: 1 | D15: 1 | E15: 3 | F15: 4 | G15: =SUM(C15:F15) | H15: Needs significant improvement. Deliverables missing.
A16: H031 | B16: Student | C16: 1 | D16: 1 | E16: 3 | F16: 3 | G16: =SUM(C16:F16) | H16: Needs significant improvement. Deliverables missing.
A17: Group 3 | Dynamic Modeling and Stability Analysis of 2-DOF Leg Mechanism for Quadruped Robot
A18: H009 | B18: Student | C18: 4 | D18: 3 | E18: 3 | F18: 3 | G18: =SUM(C18:F18) | H18: Good effort, but room for refinement.
A19: H012 | B19: Student | C19: 3 | D19: 3 | E19: 4 | F19: 4 | G19: =SUM(C19:F19) | H19: Good effort, but room for refinement.
A20: H033 | B20: Student | C20: 3 | D20: 3 | E20: 4 | F20: 4 | G20: =SUM(C20:F20) | H20: Good effort, but room for refinement.
A21: Group 4 | Critical Skid Velocity Mathematical Modeling
A22: H014 | B22: Student | C22: 1 | D22: 1 | E22: 3 | F22: 3 | G22: =SUM(C22:F22) | H22: Missing key simulation/validation components.
A23: H015 | B23: Student | C23: 1 | D23: 1 | E23: 4 | F23: 4 | G23: =SUM(C23:F23) | H23: Missing key simulation/validation components.
A24: H016 | B24: Student | C24: 1 | D24: 1 | E24: 3 | F24: 4 | G24: =SUM(C24:F24) | H24: Missing key simulation/validation components.
A25: H025 | B25: Student | C25: 1 | D25: 1 | E25: 4 | F25: 4 | G25: =SUM(C25:F25) | H25: Missing key simulation/validation components.
A26: Group 5 | Humanoid Robot - Dynamic Modeling
A27: H003 | B27: Student | C27: 3 | D27: 4 | E27: 3 | F27: 3 | G27: =SUM(C27:F27) | H27: Good effort, but room for refinement.
A28: H006 | B28: Student | C28: 3 | D28: 4 | E28: 3 | F28: 4 | G28: =SUM(C28:F28) | H28: Good effort, but room for refinement.
A29: H024 | B29: Student | C29: 4 | D29: 4 | E29: 3 | F29: 4 | G29: =SUM(C29:F29) | H29: Good effort, but room for refinement.
A30: H029 | B30: Student | C30: 3 | D30: 3 | E30: 3 | F30: 4 | G30: =SUM(C30:F30) | H30: Good effort, but room for refinement.
A31: Group 6 | Dynamic Modeling of Hydrogen Fuel Cell-Battery Hybrid Powertrain for Electric UAV
A32: H001 | B32: Student | C32: 1 | D32: 1 | E32: 4 | F32: 4 | G32: =SUM(C32:F32) | H32: Missing key simulation/validation components.
A33: H002 | B33: Student | C33: 1 | D33: 1 | E33: 3 | F33: 3 | G33: =SUM(C33:F33) | H33: Missing key simulation/validation components.
A34: Group 7 | Hexapod Robot - Mathematical Modeling
A35: H021 | B35: Student | C35: 1 | D35: 1 | E35: 4 | F35: 4 | G35: =SUM(C35:F35) | H35: Needs significant improvement. Deliverables missing.
A36: H022 | B36: Student | C36: 1 | D36: 1 | E36: 4 | F36: 3 | G36: =SUM(C36:F36) | H36: Needs significant improvement. Deliverables missing.
A37: H023 | B37: Student | C37: 1 | D37: 1 | E37: 3 | F37: 4 | G37: =SUM(C37:F37) | H37: Needs significant improvement. Deliverables missing.
A38: Group 8 | Mathematical Modeling and Dynamics of Ball Balancing Robot using 6-DOF Stewart Mechanism
A39: H059 | B39: Student | C39: 4 | D39: 3 | E39: 3 | F39: 3 | G39: =SUM(C39:F39) | H39: Good effort, but room for refinement.
A40: H060 | B40: Student | C40: 4 | D40: 3 | E40: 4 | F40: 4 | G40: =SUM(C40:F40) | H40: Good effort, but room for refinement.
...

Sheet 3_Nitu_Gupta
A1: MINI PROJECT EXHIBITION 2026 | Dynamic System Modeling (702MH0C023) | B.Tech Mechatronics Engineering, Semester IV, AY 2025-26 | NMIMS MPSTME
A2: EVALUATOR: Dr. / Ms. Nitu Gupta ROLE: Mathematics Expert
A3: Session: MORNING SESSION | 09:00 AM to 01:00 PM Date: 25 April 2026 (Saturday) Venue: AR/VR Lab, MPSTME, NMIMS
A4: ASSESSMENT FOCUS: Mathematical rigour, correctness of derivation, and simulation validation — the core learning artifact of SF-PBL.
A5: SF-PBL CORE: Mathematical derivation (ODEs, Lagrangian, state-space) is the PRIMARY artifact. Python / MATLAB code is secondary. Assess derivation first.
A6: CRITERIA KEY: C1: Derivation Correctness | C2: Equation Formulation | C3: Simulation Validation | C4: Individual Mathematical Grasp
A7: Roll No. | B7: Student Name | C7: C1 /4 | D7: C2 /4 | E7: C3 /4 | F7: C4 /4 | G7: Total /16 | H7: Comments / Feedback
A8: Group 1 | Mathematical Modeling and Dynamic Analysis of a Multi-Terrain Four-Wheeled Robot
A9: H079 | B9: Student | C9: 3 | D9: 4 | E9: 1 | F9: 4 | G9: =SUM(C9:F9) | H9: Missing key simulation/validation components.
A10: H082 | B10: Student | C10: 3 | D10: 3 | E10: 1 | F10: 3 | G10: =SUM(C10:F10) | H10: Missing key simulation/validation components.
A11: H084 | B11: Student | C11: 4 | D11: 4 | E11: 1 | F11: 3 | G11: =SUM(C11:F11) | H11: Missing key simulation/validation components.
A12: Group 2 | Modeling Rocket Landing - Docking
A13: H004 | B13: Student | C13: 4 | D13: 4 | E13: 4 | F13: 3 | G13: =SUM(C13:F13) | H13: Excellent work! Clear and well-presented.
A14: H005 | B14: Student | C14: 0 | D14: 0 | E14: 0 | F14: 0 | G14: =SUM(C14:F14) | H14: Absent throughout.
A15: H028 | B15: Student | C15: 4 | D15: 4 | E15: 4 | F15: 4 | G15: =SUM(C15:F15) | H15: Excellent work! Clear and well-presented.
A16: H031 | B16: Student | C16: 3 | D16: 3 | E16: 4 | F16: 3 | G16: =SUM(C16:F16) | H16: Good effort, but room for refinement.
A17: Group 3 | Dynamic Modeling and Stability Analysis of 2-DOF Leg Mechanism for Quadruped Robot
A18: H009 | B18: Student | C18: 3 | D18: 4 | E18: 3 | F18: 4 | G18: =SUM(C18:F18) | H18: Good effort, but room for refinement.
A19: H012 | B19: Student | C19: 4 | D19: 3 | E19: 3 | F19: 3 | G19: =SUM(C19:F19) | H19: Good effort, but room for refinement.
A20: H033 | B20: Student | C20: 3 | D20: 4 | E20: 4 | F20: 3 | G20: =SUM(C20:F20) | H20: Good effort, but room for refinement.
A21: Group 4 | Critical Skid Velocity Mathematical Modeling
A22: H014 | B22: Student | C22: 1 | D22: 1 | E22: 1 | F22: 3 | G22: =SUM(C22:F22) | H22: Missing key simulation/validation components.
A23: H015 | B23: Student | C23: 1 | D23: 1 | E23: 1 | F23: 3 | G23: =SUM(C23:F23) | H23: Missing key simulation/validation components.
A24: H016 | B24: Student | C24: 1 | D24: 1 | E24: 1 | F24: 4 | G24: =SUM(C24:F24) | H24: Missing key simulation/validation components.
A25: H025 | B25: Student | C25: 1 | D25: 1 | E25: 1 | F25: 4 | G25: =SUM(C25:F25) | H25: Missing key simulation/validation components.
A26: Group 5 | Humanoid Robot - Dynamic Modeling
A27: H003 | B27: Student | C27: 3 | D27: 4 | E27: 3 | F27: 4 | G27: =SUM(C27:F27) | H27: Good effort, but room for refinement.
A28: H006 | B28: Student | C28: 4 | D28: 3 | E28: 4 | F28: 3 | G28: =SUM(C28:F28) | H28: Good effort, but room for refinement.
A29: H024 | B29: Student | C29: 3 | D29: 3 | E29: 3 | F29: 4 | G29: =SUM(C29:F29) | H29: Good effort, but room for refinement.
A30: H029 | B30: Student | C30: 4 | D30: 4 | E30: 4 | F30: 4 | G30: =SUM(C30:F30) | H30: Excellent work! Clear and well-presented.
A31: Group 6 | Dynamic Modeling of Hydrogen Fuel Cell-Battery Hybrid Powertrain for Electric UAV
A32: H001 | B32: Student | C32: 1 | D32: 1 | E32: 1 | F32: 3 | G32: =SUM(C32:F32) | H32: Missing key simulation/validation components.
A33: H002 | B33: Student | C33: 1 | D33: 1 | E33: 1 | F33: 4 | G33: =SUM(C33:F33) | H33: Missing key simulation/validation components.
A34: Group 7 | Hexapod Robot - Mathematical Modeling
A35: H021 | B35: Student | C35: 4 | D35: 3 | E35: 4 | F35: 4 | G35: =SUM(C35:F35) | H35: Good effort, but room for refinement.
A36: H022 | B36: Student | C36: 4 | D36: 4 | E36: 3 | F36: 3 | G36: =SUM(C36:F36) | H36: Good effort, but room for refinement.
A37: H023 | B37: Student | C37: 3 | D37: 3 | E37: 4 | F37: 4 | G37: =SUM(C37:F37) | H37: Good effort, but room for refinement.
A38: Group 8 | Mathematical Modeling and Dynamics of Ball Balancing Robot using 6-DOF Stewart Mechanism
A39: H059 | B39: Student | C39: 3 | D39: 3 | E39: 4 | F39: 4 | G39: =SUM(C39:F39) | H39: Good effort, but room for refinement.
A40: H060 | B40: Student | C40: 4 | D40: 4 | E40: 4 | F40: 4 | G40: =SUM(C40:F40) | H40: Excellent work! Clear and well-presented.
...

Sheet 4_Mahendra_Kane
A1: MINI PROJECT EXHIBITION 2026 | Dynamic System Modeling (702MH0C023) | B.Tech Mechatronics Engineering, Semester IV, AY 2025-26 | NMIMS MPSTME
A2: EVALUATOR: Mr. Mahendra Kane ROLE: Industrial Automation & Industry 4.0 Expert (Siemens Ltd)
A3: Session: MORNING SESSION | 09:00 AM to 01:00 PM Date: 25 April 2026 (Saturday) Venue: AR/VR Lab, MPSTME, NMIMS
A4: ASSESSMENT FOCUS: Industrial automation relevance, control system integration potential, and Digital Twin / Industry 4.0 readiness of the mathematical model and simulation.
A5: SF-PBL: Assess whether the simulation-based model can bridge into real PLC / SCADA / motion-control scenarios and contribute to an Industry 4.0 digital strategy.
A6: CRITERIA KEY: C1: Industrial System Relevance | C2: Control & Actuation Alignment | C3: Digital Twin / Industry 4.0 Potential | C4: Individual Automation Q&A
A7: Roll No. | B7: Student Name | C7: C1 /5 | D7: C2 /5 | E7: C3 /5 | F7: C4 /5 | G7: Total /20 | H7: Comments / Feedback
A8: Group 1 | Mathematical Modeling and Dynamic Analysis of a Multi-Terrain Four-Wheeled Robot
A9: H079 | B9: Student | C9: 5 | D9: 4 | E9: 2 | F9: 5 | G9: =SUM(C9:F9) | H9: Missing key simulation/validation components.
A10: H082 | B10: Student | C10: 4 | D10: 5 | E10: 2 | F10: 4 | G10: =SUM(C10:F10) | H10: Missing key simulation/validation components.
A11: H084 | B11: Student | C11: 4 | D11: 5 | E11: 2 | F11: 4 | G11: =SUM(C11:F11) | H11: Missing key simulation/validation components.
A12: Group 2 | Modeling Rocket Landing - Docking
A13: H004 | B13: Student | C13: 4 | D13: 5 | E13: 5 | F13: 4 | G13: =SUM(C13:F13) | H13: Good effort, but room for refinement.
A14: H005 | B14: Student | C14: 0 | D14: 0 | E14: 0 | F14: 0 | G14: =SUM(C14:F14) | H14: Absent throughout.
A15: H028 | B15: Student | C15: 4 | D15: 4 | E15: 5 | F15: 5 | G15: =SUM(C15:F15) | H15: Good effort, but room for refinement.
A16: H031 | B16: Student | C16: 4 | D16: 5 | E16: 4 | F16: 5 | G16: =SUM(C16:F16) | H16: Good effort, but room for refinement.
A17: Group 3 | Dynamic Modeling and Stability Analysis of 2-DOF Leg Mechanism for Quadruped Robot
A18: H009 | B18: Student | C18: 4 | D18: 5 | E18: 5 | F18: 5 | G18: =SUM(C18:F18) | H18: Good effort, but room for refinement.
A19: H012 | B19: Student | C19: 5 | D19: 4 | E19: 5 | F19: 5 | G19: =SUM(C19:F19) | H19: Good effort, but room for refinement.
A20: H033 | B20: Student | C20: 4 | D20: 4 | E20: 5 | F20: 5 | G20: =SUM(C20:F20) | H20: Good effort, but room for refinement.
A21: Group 4 | Critical Skid Velocity Mathematical Modeling
A22: H014 | B22: Student | C22: 5 | D22: 2 | E22: 2 | F22: 4 | G22: =SUM(C22:F22) | H22: Missing key simulation/validation components.
A23: H015 | B23: Student | C23: 5 | D23: 2 | E23: 2 | F23: 4 | G23: =SUM(C23:F23) | H23: Missing key simulation/validation components.
A24: H016 | B24: Student | C24: 4 | D24: 2 | E24: 2 | F24: 4 | G24: =SUM(C24:F24) | H24: Missing key simulation/validation components.
A25: H025 | B25: Student | C25: 4 | D25: 2 | E25: 2 | F25: 5 | G25: =SUM(C25:F25) | H25: Missing key simulation/validation components.
A26: Group 5 | Humanoid Robot - Dynamic Modeling
A27: H003 | B27: Student | C27: 4 | D27: 5 | E27: 5 | F27: 5 | G27: =SUM(C27:F27) | H27: Good effort, but room for refinement.
A28: H006 | B28: Student | C28: 4 | D28: 5 | E28: 4 | F28: 4 | G28: =SUM(C28:F28) | H28: Good effort, but room for refinement.
A29: H024 | B29: Student | C29: 5 | D29: 5 | E29: 4 | F29: 5 | G29: =SUM(C29:F29) | H29: Good effort, but room for refinement.
A30: H029 | B30: Student | C30: 5 | D30: 5 | E30: 5 | F30: 5 | G30: =SUM(C30:F30) | H30: Excellent work! Clear and well-presented.
A31: Group 6 | Dynamic Modeling of Hydrogen Fuel Cell-Battery Hybrid Powertrain for Electric UAV
A32: H001 | B32: Student | C32: 4 | D32: 2 | E32: 2 | F32: 5 | G32: =SUM(C32:F32) | H32: Missing key simulation/validation components.
A33: H002 | B33: Student | C33: 4 | D33: 2 | E33: 2 | F33: 5 | G33: =SUM(C33:F33) | H33: Missing key simulation/validation components.
A34: Group 7 | Hexapod Robot - Mathematical Modeling
A35: H021 | B35: Student | C35: 5 | D35: 5 | E35: 5 | F35: 5 | G35: =SUM(C35:F35) | H35: Excellent work! Clear and well-presented.
A36: H022 | B36: Student | C36: 4 | D36: 4 | E36: 4 | F36: 4 | G36: =SUM(C36:F36) | H36: Good effort, but room for refinement.
A37: H023 | B37: Student | C37: 5 | D37: 5 | E37: 5 | F37: 5 | G37: =SUM(C37:F37) | H37: Excellent work! Clear and well-presented.
A38: Group 8 | Mathematical Modeling and Dynamics of Ball Balancing Robot using 6-DOF Stewart Mechanism
A39: H059 | B39: Student | C39: 5 | D39: 4 | E39: 5 | F39: 4 | G39: =SUM(C39:F39) | H39: Good effort, but room for refinement.
A40: H060 | B40: Student | C40: 5 | D40: 4 | E40: 5 | F40: 5 | G40: =SUM(C40:F40) | H40: Good effort, but room for refinement.
...

Sheet 5_Parminder_Jandoo
A1: MINI PROJECT EXHIBITION 2026 | Dynamic System Modeling (702MH0C023) | B.Tech Mechatronics Engineering, Semester IV, AY 2025-26 | NMIMS MPSTME
A2: EVALUATOR: Ms. Parminder Jandoo ROLE: Communication & Presentation Expert
A3: Session: MORNING (09:00-13:00) + AFTERNOON (13:30-17:00) -- Combined 16 Marks Date: 25 April 2026 (Saturday) Venue: AR/VR Lab, MPSTME, NMIMS
A4: ASSESSMENT FOCUS: Communication quality, delivery, body language, and presentation skills observed across the morning demo and the afternoon formal presentation.
A5: SF-PBL: Assess how clearly each student communicates their simulation journey: problem identification -> math model -> simulation results -> validation.
A6: CRITERIA KEY: C1: Technical Clarity | C2: Confidence & Q&A Response | C3: Presentation Delivery | C4: Overall Communication Impact
A7: Roll No. | B7: Student Name | C7: C1 /4 | D7: C2 /4 | E7: C3 /4 | F7: C4 /4 | G7: Total /16 | H7: Comments / Feedback
A8: Group 1 | Mathematical Modeling and Dynamic Analysis of a Multi-Terrain Four-Wheeled Robot
A9: H079 | B9: Student | C9: 4 | D9: 3 | E9: 3 | F9: 4 | G9: =SUM(C9:F9) | H9: Good effort, but room for refinement.
A10: H082 | B10: Student | C10: 3 | D10: 3 | E10: 4 | F10: 4 | G10: =SUM(C10:F10) | H10: Good effort, but room for refinement.
A11: H084 | B11: Student | C11: 3 | D11: 3 | E11: 4 | F11: 3 | G11: =SUM(C11:F11) | H11: Good effort, but room for refinement.
A12: Group 2 | Modeling Rocket Landing - Docking
A13: H004 | B13: Student | C13: 1 | D13: 3 | E13: 3 | F13: 4 | G13: =SUM(C13:F13) | H13: Needs significant improvement. Deliverables missing.
A14: H005 | B14: Student | C14: 0 | D14: 0 | E14: 0 | F14: 0 | G14: =SUM(C14:F14) | H14: Absent throughout.
A15: H028 | B15: Student | C15: 1 | D15: 4 | E15: 4 | F15: 4 | G15: =SUM(C15:F15) | H15: Needs significant improvement. Deliverables missing.
A16: H031 | B16: Student | C16: 1 | D16: 4 | E16: 4 | F16: 3 | G16: =SUM(C16:F16) | H16: Needs significant improvement. Deliverables missing.
A17: Group 3 | Dynamic Modeling and Stability Analysis of 2-DOF Leg Mechanism for Quadruped Robot
A18: H009 | B18: Student | C18: 4 | D18: 4 | E18: 4 | F18: 4 | G18: =SUM(C18:F18) | H18: Excellent work! Clear and well-presented.
A19: H012 | B19: Student | C19: 3 | D19: 4 | E19: 4 | F19: 4 | G19: =SUM(C19:F19) | H19: Good effort, but room for refinement.
A20: H033 | B20: Student | C20: 3 | D20: 3 | E20: 3 | F20: 4 | G20: =SUM(C20:F20) | H20: Good effort, but room for refinement.
A21: Group 4 | Critical Skid Velocity Mathematical Modeling
A22: H014 | B22: Student | C22: 1 | D22: 4 | E22: 4 | F22: 4 | G22: =SUM(C22:F22) | H22: Missing key simulation/validation components.
A23: H015 | B23: Student | C23: 1 | D23: 3 | E23: 3 | F23: 4 | G23: =SUM(C23:F23) | H23: Missing key simulation/validation components.
A24: H016 | B24: Student | C24: 1 | D24: 3 | E24: 3 | F24: 3 | G24: =SUM(C24:F24) | H24: Missing key simulation/validation components.
A25: H025 | B25: Student | C25: 1 | D25: 4 | E25: 4 | F25: 4 | G25: =SUM(C25:F25) | H25: Missing key simulation/validation components.
A26: Group 5 | Humanoid Robot - Dynamic Modeling
A27: H003 | B27: Student | C27: 4 | D27: 4 | E27: 4 | F27: 3 | G27: =SUM(C27:F27) | H27: Excellent work! Clear and well-presented.
A28: H006 | B28: Student | C28: 4 | D28: 3 | E28: 3 | F28: 3 | G28: =SUM(C28:F28) | H28: Good effort, but room for refinement.
A29: H024 | B29: Student | C29: 4 | D29: 3 | E29: 3 | F29: 3 | G29: =SUM(C29:F29) | H29: Good effort, but room for refinement.
A30: H029 | B30: Student | C30: 4 | D30: 4 | E30: 3 | F30: 4 | G30: =SUM(C30:F30) | H30: Good effort, but room for refinement.
A31: Group 6 | Dynamic Modeling of Hydrogen Fuel Cell-Battery Hybrid Powertrain for Electric UAV
A32: H001 | B32: Student | C32: 1 | D32: 3 | E32: 0 | F32: 1 | G32: =SUM(C32:F32) | H32: Missed afternoon formal presentation.
A33: H002 | B33: Student | C33: 1 | D33: 3 | E33: 0 | F33: 1 | G33: =SUM(C33:F33) | H33: Missed afternoon formal presentation.
A34: Group 7 | Hexapod Robot - Mathematical Modeling
A35: H021 | B35: Student | C35: 1 | D35: 4 | E35: 4 | F35: 3 | G35: =SUM(C35:F35) | H35: Needs significant improvement. Deliverables missing.
A36: H022 | B36: Student | C36: 1 | D36: 4 | E36: 3 | F36: 4 | G36: =SUM(C36:F36) | H36: Needs significant improvement. Deliverables missing.
A37: H023 | B37: Student | C37: 1 | D37: 4 | E37: 4 | F37: 4 | G37: =SUM(C37:F37) | H37: Needs significant improvement. Deliverables missing.
A38: Group 8 | Mathematical Modeling and Dynamics of Ball Balancing Robot using 6-DOF Stewart Mechanism
A39: H059 | B39: Student | C39: 4 | D39: 3 | E39: 3 | F39: 4 | G39: =SUM(C39:F39) | H39: Good effort, but room for refinement.
A40: H060 | B40: Student | C40: 3 | D40: 4 | E40: 4 | F40: 3 | G40: =SUM(C40:F40) | H40: Good effort, but room for refinement.
...

Sheet 6_Debasis_Dash
A1: MINI PROJECT EXHIBITION 2026 | Dynamic System Modeling (702MH0C023) | B.Tech Mechatronics Engineering, Semester IV, AY 2025-26 | NMIMS MPSTME
A2: EVALUATOR: Dr. Debasis Dash ROLE: HR & Behavioural Science Expert (MPSTME, NMIMS)
A3: Session: MORNING SESSION | 09:00 AM to 01:00 PM Date: 25 April 2026 (Saturday) Venue: AR/VR Lab, MPSTME, NMIMS
A4: ASSESSMENT FOCUS: Team collaboration, professional conduct, problem-solving mindset, and individual self-awareness within the SF-PBL group project context.
A5: SF-PBL: Engineering education goes beyond equations — assess how well students collaborate, reflect on challenges, and demonstrate professional and ethical behaviour.
A6: CRITERIA KEY: C1: Team Collaboration | C2: Problem-Solving Mindset | C3: Individual Professionalism | C4: Individual Self-Awareness
A7: Roll No. | B7: Student Name | C7: C1 /4 | D7: C2 /4 | E7: C3 /4 | F7: C4 /4 | G7: Total /16 | H7: Comments / Feedback
A8: Group 1 | Mathematical Modeling and Dynamic Analysis of a Multi-Terrain Four-Wheeled Robot
A9: H079 | B9: Student | C9: 4 | D9: 4 | E9: 3 | F9: 3 | G9: =SUM(C9:F9) | H9: Good effort, but room for refinement.
A10: H082 | B10: Student | C10: 3 | D10: 4 | E10: 3 | F10: 3 | G10: =SUM(C10:F10) | H10: Good effort, but room for refinement.
A11: H084 | B11: Student | C11: 3 | D11: 3 | E11: 3 | F11: 3 | G11: =SUM(C11:F11) | H11: Good effort, but room for refinement.
A12: Group 2 | Modeling Rocket Landing - Docking
A13: H004 | B13: Student | C13: 3 | D13: 4 | E13: 3 | F13: 3 | G13: =SUM(C13:F13) | H13: Good effort, but room for refinement.
A14: H005 | B14: Student | C14: 0 | D14: 0 | E14: 0 | F14: 0 | G14: =SUM(C14:F14) | H14: Absent throughout.
A15: H028 | B15: Student | C15: 3 | D15: 4 | E15: 3 | F15: 4 | G15: =SUM(C15:F15) | H15: Good effort, but room for refinement.
A16: H031 | B16: Student | C16: 3 | D16: 3 | E16: 4 | F16: 4 | G16: =SUM(C16:F16) | H16: Good effort, but room for refinement.
A17: Group 3 | Dynamic Modeling and Stability Analysis of 2-DOF Leg Mechanism for Quadruped Robot
A18: H009 | B18: Student | C18: 1 | D18: 1 | E18: 4 | F18: 4 | G18: =SUM(C18:F18) | H18: Needs significant improvement. Deliverables missing.
A19: H012 | B19: Student | C19: 1 | D19: 1 | E19: 3 | F19: 4 | G19: =SUM(C19:F19) | H19: Needs significant improvement. Deliverables missing.
A20: H033 | B20: Student | C20: 1 | D20: 1 | E20: 4 | F20: 3 | G20: =SUM(C20:F20) | H20: Needs significant improvement. Deliverables missing.
A21: Group 4 | Critical Skid Velocity Mathematical Modeling
A22: H014 | B22: Student | C22: 1 | D22: 1 | E22: 3 | F22: 3 | G22: =SUM(C22:F22) | H22: Missing key simulation/validation components.
A23: H015 | B23: Student | C23: 1 | D23: 1 | E23: 3 | F23: 4 | G23: =SUM(C23:F23) | H23: Missing key simulation/validation components.
A24: H016 | B24: Student | C24: 1 | D24: 1 | E24: 4 | F24: 4 | G24: =SUM(C24:F24) | H24: Missing key simulation/validation components.
A25: H025 | B25: Student | C25: 1 | D25: 1 | E25: 3 | F25: 3 | G25: =SUM(C25:F25) | H25: Missing key simulation/validation components.
A26: Group 5 | Humanoid Robot - Dynamic Modeling
A27: H003 | B27: Student | C27: 3 | D27: 4 | E27: 3 | F27: 3 | G27: =SUM(C27:F27) | H27: Good effort, but room for refinement.
A28: H006 | B28: Student | C28: 3 | D28: 3 | E28: 4 | F28: 4 | G28: =SUM(C28:F28) | H28: Good effort, but room for refinement.
A29: H024 | B29: Student | C29: 4 | D29: 4 | E29: 4 | F29: 4 | G29: =SUM(C29:F29) | H29: Excellent work! Clear and well-presented.
A30: H029 | B30: Student | C30: 3 | D30: 3 | E30: 4 | F30: 4 | G30: =SUM(C30:F30) | H30: Good effort, but room for refinement.
A31: Group 6 | Dynamic Modeling of Hydrogen Fuel Cell-Battery Hybrid Powertrain for Electric UAV
A32: H001 | B32: Student | C32: 1 | D32: 1 | E32: 4 | F32: 4 | G32: =SUM(C32:F32) | H32: Missing key simulation/validation components.
A33: H002 | B33: Student | C33: 1 | D33: 1 | E33: 4 | F33: 3 | G33: =SUM(C33:F33) | H33: Missing key simulation/validation components.
A34: Group 7 | Hexapod Robot - Mathematical Modeling
A35: H021 | B35: Student | C35: 4 | D35: 4 | E35: 4 | F35: 4 | G35: =SUM(C35:F35) | H35: Excellent work! Clear and well-presented.
A36: H022 | B36: Student | C36: 3 | D36: 4 | E36: 4 | F36: 4 | G36: =SUM(C36:F36) | H36: Good effort, but room for refinement.
A37: H023 | B37: Student | C37: 4 | D37: 3 | E37: 3 | F37: 4 | G37: =SUM(C37:F37) | H37: Good effort, but room for refinement.
A38: Group 8 | Mathematical Modeling and Dynamics of Ball Balancing Robot using 6-DOF Stewart Mechanism
A39: H059 | B39: Student | C39: 3 | D39: 3 | E39: 3 | F39: 4 | G39: =SUM(C39:F39) | H39: Good effort, but room for refinement.
A40: H060 | B40: Student | C40: 3 | D40: 4 | E40: 4 | F40: 3 | G40: =SUM(C40:F40) | H40: Good effort, but room for refinement.
...

Sheet 7_Marks_Summary
A1: MINI PROJECT EXHIBITION 2026 -- MARKS SUMMARY | Final Score out of 100
A2: 6 Judges = 100 Total | Panchal /16 + Chandarana /16 + Gupta /16 + Kane /20 + Jandoo /16 + Dash /16 = FINAL /100 Columns E–J are pulled automatically from evaluator sheets. Enter marks ONLY on the individual evaluator tabs (1–6).
A3: Grp # | B3: Roll No. | C3: Student Name | D3: Project Title | E3: Kamlesh Panchal /16 | F3: Hasti Chandarana /16 | G3: Nitu Gupta /16 | H3: Mahendra Kane /20 | I3: Parminder Jandoo /16 | J3: Debasis Dash /16 | K3: FINAL MARKS /100
A4: 1 | B4: H079 | C4: Student | D4: Mathematical Modeling and Dynamic Analysis of a Mu... | E4: ='1_Kamlesh_Panchal'!G9 | F4: ='2_Hasti_Chandarana'!G9 | G4: ='3_Nitu_Gupta'!G9 | H4: ='4_Mahendra_Kane'!G9 | I4: ='5_Parminder_Jandoo'!G9 | J4: ='6_Debasis_Dash'!G9 | K4: =E4+F4+G4+H4+I4+J4
A5: 1 | B5: H082 | C5: Student | D5: Mathematical Modeling and Dynamic Analysis of a Mu... | E5: ='1_Kamlesh_Panchal'!G10 | F5: ='2_Hasti_Chandarana'!G10 | G5: ='3_Nitu_Gupta'!G10 | H5: ='4_Mahendra_Kane'!G10 | I5: ='5_Parminder_Jandoo'!G10 | J5: ='6_Debasis_Dash'!G10 | K5: =E5+F5+G5+H5+I5+J5
A6: 1 | B6: H084 | C6: Student | D6: Mathematical Modeling and Dynamic Analysis of a Mu... | E6: ='1_Kamlesh_Panchal'!G11 | F6: ='2_Hasti_Chandarana'!G11 | G6: ='3_Nitu_Gupta'!G11 | H6: ='4_Mahendra_Kane'!G11 | I6: ='5_Parminder_Jandoo'!G11 | J6: ='6_Debasis_Dash'!G11 | K6: =E6+F6+G6+H6+I6+J6
A7: 2 | B7: H004 | C7: Student | D7: Modeling Rocket Landing - Docking | E7: ='1_Kamlesh_Panchal'!G13 | F7: ='2_Hasti_Chandarana'!G13 | G7: ='3_Nitu_Gupta'!G13 | H7: ='4_Mahendra_Kane'!G13 | I7: ='5_Parminder_Jandoo'!G13 | J7: ='6_Debasis_Dash'!G13 | K7: =E7+F7+G7+H7+I7+J7
A8: 2 | B8: H005 | C8: Student | D8: Modeling Rocket Landing - Docking | E8: ='1_Kamlesh_Panchal'!G14 | F8: ='2_Hasti_Chandarana'!G14 | G8: ='3_Nitu_Gupta'!G14 | H8: ='4_Mahendra_Kane'!G14 | I8: ='5_Parminder_Jandoo'!G14 | J8: ='6_Debasis_Dash'!G14 | K8: =E8+F8+G8+H8+I8+J8
A9: 2 | B9: H028 | C9: Student | D9: Modeling Rocket Landing - Docking | E9: ='1_Kamlesh_Panchal'!G15 | F9: ='2_Hasti_Chandarana'!G15 | G9: ='3_Nitu_Gupta'!G15 | H9: ='4_Mahendra_Kane'!G15 | I9: ='5_Parminder_Jandoo'!G15 | J9: ='6_Debasis_Dash'!G15 | K9: =E9+F9+G9+H9+I9+J9
A10: 2 | B10: H031 | C10: Student | D10: Modeling Rocket Landing - Docking | E10: ='1_Kamlesh_Panchal'!G16 | F10: ='2_Hasti_Chandarana'!G16 | G10: ='3_Nitu_Gupta'!G16 | H10: ='4_Mahendra_Kane'!G16 | I10: ='5_Parminder_Jandoo'!G16 | J10: ='6_Debasis_Dash'!G16 | K10: =E10+F10+G10+H10+I10+J10
A11: 3 | B11: H009 | C11: Student | D11: Dynamic Modeling and Stability Analysis of 2-DOF L... | E11: ='1_Kamlesh_Panchal'!G18 | F11: ='2_Hasti_Chandarana'!G18 | G11: ='3_Nitu_Gupta'!G18 | H11: ='4_Mahendra_Kane'!G18 | I11: ='5_Parminder_Jandoo'!G18 | J11: ='6_Debasis_Dash'!G18 | K11: =E11+F11+G11+H11+I11+J11
A12: 3 | B12: H012 | C12: Student | D12: Dynamic Modeling and Stability Analysis of 2-DOF L... | E12: ='1_Kamlesh_Panchal'!G19 | F12: ='2_Hasti_Chandarana'!G19 | G12: ='3_Nitu_Gupta'!G19 | H12: ='4_Mahendra_Kane'!G19 | I12: ='5_Parminder_Jandoo'!G19 | J12: ='6_Debasis_Dash'!G19 | K12: =E12+F12+G12+H12+I12+J12
A13: 3 | B13: H033 | C13: Student | D13: Dynamic Modeling and Stability Analysis of 2-DOF L... | E13: ='1_Kamlesh_Panchal'!G20 | F13: ='2_Hasti_Chandarana'!G20 | G13: ='3_Nitu_Gupta'!G20 | H13: ='4_Mahendra_Kane'!G20 | I13: ='5_Parminder_Jandoo'!G20 | J13: ='6_Debasis_Dash'!G20 | K13: =E13+F13+G13+H13+I13+J13
A14: 4 | B14: H014 | C14: Student | D14: Critical Skid Velocity Mathematical Modeling | E14: ='1_Kamlesh_Panchal'!G22 | F14: ='2_Hasti_Chandarana'!G22 | G14: ='3_Nitu_Gupta'!G22 | H14: ='4_Mahendra_Kane'!G22 | I14: ='5_Parminder_Jandoo'!G22 | J14: ='6_Debasis_Dash'!G22 | K14: =E14+F14+G14+H14+I14+J14
A15: 4 | B15: H015 | C15: Student | D15: Critical Skid Velocity Mathematical Modeling | E15: ='1_Kamlesh_Panchal'!G23 | F15: ='2_Hasti_Chandarana'!G23 | G15: ='3_Nitu_Gupta'!G23 | H15: ='4_Mahendra_Kane'!G23 | I15: ='5_Parminder_Jandoo'!G23 | J15: ='6_Debasis_Dash'!G23 | K15: =E15+F15+G15+H15+I15+J15
A16: 4 | B16: H016 | C16: Student | D16: Critical Skid Velocity Mathematical Modeling | E16: ='1_Kamlesh_Panchal'!G24 | F16: ='2_Hasti_Chandarana'!G24 | G16: ='3_Nitu_Gupta'!G24 | H16: ='4_Mahendra_Kane'!G24 | I16: ='5_Parminder_Jandoo'!G24 | J16: ='6_Debasis_Dash'!G24 | K16: =E16+F16+G16+H16+I16+J16
A17: 4 | B17: H025 | C17: Student | D17: Critical Skid Velocity Mathematical Modeling | E17: ='1_Kamlesh_Panchal'!G25 | F17: ='2_Hasti_Chandarana'!G25 | G17: ='3_Nitu_Gupta'!G25 | H17: ='4_Mahendra_Kane'!G25 | I17: ='5_Parminder_Jandoo'!G25 | J17: ='6_Debasis_Dash'!G25 | K17: =E17+F17+G17+H17+I17+J17
A18: 5 | B18: H003 | C18: Student | D18: Humanoid Robot - Dynamic Modeling | E18: ='1_Kamlesh_Panchal'!G27 | F18: ='2_Hasti_Chandarana'!G27 | G18: ='3_Nitu_Gupta'!G27 | H18: ='4_Mahendra_Kane'!G27 | I18: ='5_Parminder_Jandoo'!G27 | J18: ='6_Debasis_Dash'!G27 | K18: =E18+F18+G18+H18+I18+J18
A19: 5 | B19: H006 | C19: Student | D19: Humanoid Robot - Dynamic Modeling | E19: ='1_Kamlesh_Panchal'!G28 | F19: ='2_Hasti_Chandarana'!G28 | G19: ='3_Nitu_Gupta'!G28 | H19: ='4_Mahendra_Kane'!G28 | I19: ='5_Parminder_Jandoo'!G28 | J19: ='6_Debasis_Dash'!G28 | K19: =E19+F19+G19+H19+I19+J19
A20: 5 | B20: H024 | C20: Student | D20: Humanoid Robot - Dynamic Modeling | E20: ='1_Kamlesh_Panchal'!G29 | F20: ='2_Hasti_Chandarana'!G29 | G20: ='3_Nitu_Gupta'!G29 | H20: ='4_Mahendra_Kane'!G29 | I20: ='5_Parminder_Jandoo'!G29 | J20: ='6_Debasis_Dash'!G29 | K20: =E20+F20+G20+H20+I20+J20
A21: 5 | B21: H029 | C21: Student | D21: Humanoid Robot - Dynamic Modeling | E21: ='1_Kamlesh_Panchal'!G30 | F21: ='2_Hasti_Chandarana'!G30 | G21: ='3_Nitu_Gupta'!G30 | H21: ='4_Mahendra_Kane'!G30 | I21: ='5_Parminder_Jandoo'!G30 | J21: ='6_Debasis_Dash'!G30 | K21: =E21+F21+G21+H21+I21+J21
A22: 6 | B22: H001 | C22: Student | D22: Dynamic Modeling of Hydrogen Fuel Cell-Battery Hyb... | E22: ='1_Kamlesh_Panchal'!G32 | F22: ='2_Hasti_Chandarana'!G32 | G22: ='3_Nitu_Gupta'!G32 | H22: ='4_Mahendra_Kane'!G32 | I22: ='5_Parminder_Jandoo'!G32 | J22: ='6_Debasis_Dash'!G32 | K22: =E22+F22+G22+H22+I22+J22
A23: 6 | B23: H002 | C23: Student | D23: Dynamic Modeling of Hydrogen Fuel Cell-Battery Hyb... | E23: ='1_Kamlesh_Panchal'!G33 | F23: ='2_Hasti_Chandarana'!G33 | G23: ='3_Nitu_Gupta'!G33 | H23: ='4_Mahendra_Kane'!G33 | I23: ='5_Parminder_Jandoo'!G33 | J23: ='6_Debasis_Dash'!G33 | K23: =E23+F23+G23+H23+I23+J23
A24: 7 | B24: H021 | C24: Student | D24: Hexapod Robot - Mathematical Modeling | E24: ='1_Kamlesh_Panchal'!G35 | F24: ='2_Hasti_Chandarana'!G35 | G24: ='3_Nitu_Gupta'!G35 | H24: ='4_Mahendra_Kane'!G35 | I24: ='5_Parminder_Jandoo'!G35 | J24: ='6_Debasis_Dash'!G35 | K24: =E24+F24+G24+H24+I24+J24
A25: 7 | B25: H022 | C25: Student | D25: Hexapod Robot - Mathematical Modeling | E25: ='1_Kamlesh_Panchal'!G36 | F25: ='2_Hasti_Chandarana'!G36 | G25: ='3_Nitu_Gupta'!G36 | H25: ='4_Mahendra_Kane'!G36 | I25: ='5_Parminder_Jandoo'!G36 | J25: ='6_Debasis_Dash'!G36 | K25: =E25+F25+G25+H25+I25+J25
A26: 7 | B26: H023 | C26: Student | D26: Hexapod Robot - Mathematical Modeling | E26: ='1_Kamlesh_Panchal'!G37 | F26: ='2_Hasti_Chandarana'!G37 | G26: ='3_Nitu_Gupta'!G37 | H26: ='4_Mahendra_Kane'!G37 | I26: ='5_Parminder_Jandoo'!G37 | J26: ='6_Debasis_Dash'!G37 | K26: =E26+F26+G26+H26+I26+J26
A27: 8 | B27: H059 | C27: Student | D27: Mathematical Modeling and Dynamics of Ball Balanci... | E27: ='1_Kamlesh_Panchal'!G39 | F27: ='2_Hasti_Chandarana'!G39 | G27: ='3_Nitu_Gupta'!G39 | H27: ='4_Mahendra_Kane'!G39 | I27: ='5_Parminder_Jandoo'!G39 | J27: ='6_Debasis_Dash'!G39 | K27: =E27+F27+G27+H27+I27+J27
A28: 8 | B28: H060 | C28: Student | D28: Mathematical Modeling and Dynamics of Ball Balanci... | E28: ='1_Kamlesh_Panchal'!G40 | F28: ='2_Hasti_Chandarana'!G40 | G28: ='3_Nitu_Gupta'!G40 | H28: ='4_Mahendra_Kane'!G40 | I28: ='5_Parminder_Jandoo'!G40 | J28: ='6_Debasis_Dash'!G40 | K28: =E28+F28+G28+H28+I28+J28
A29: 8 | B29: H062 | C29: Student | D29: Mathematical Modeling and Dynamics of Ball Balanci... | E29: ='1_Kamlesh_Panchal'!G41 | F29: ='2_Hasti_Chandarana'!G41 | G29: ='3_Nitu_Gupta'!G41 | H29: ='4_Mahendra_Kane'!G41 | I29: ='5_Parminder_Jandoo'!G41 | J29: ='6_Debasis_Dash'!G41 | K29: =E29+F29+G29+H29+I29+J29
A30: 9 | B30: H035 | C30: Student | D30: Dynamic Modelling of Sensor-Integrated Remotely Op... | E30: ='1_Kamlesh_Panchal'!G43 | F30: ='2_Hasti_Chandarana'!G43 | G30: ='3_Nitu_Gupta'!G43 | H30: ='4_Mahendra_Kane'!G43 | I30: ='5_Parminder_Jandoo'!G43 | J30: ='6_Debasis_Dash'!G43 | K30: =E30+F30+G30+H30+I30+J30
A31: 9 | B31: H040 | C31: Student | D31: Dynamic Modelling of Sensor-Integrated Remotely Op... | E31: ='1_Kamlesh_Panchal'!G44 | F31: ='2_Hasti_Chandarana'!G44 | G31: ='3_Nitu_Gupta'!G44 | H31: ='4_Mahendra_Kane'!G44 | I31: ='5_Parminder_Jandoo'!G44 | J31: ='6_Debasis_Dash'!G44 | K31: =E31+F31+G31+H31+I31+J31
A32: 9 | B32: H046 | C32: Student | D32: Dynamic Modelling of Sensor-Integrated Remotely Op... | E32: ='1_Kamlesh_Panchal'!G45 | F32: ='2_Hasti_Chandarana'!G45 | G32: ='3_Nitu_Gupta'!G45 | H32: ='4_Mahendra_Kane'!G45 | I32: ='5_Parminder_Jandoo'!G45 | J32: ='6_Debasis_Dash'!G45 | K32: =E32+F32+G32+H32+I32+J32
A33: 9 | B33: H047 | C33: Student | D33: Dynamic Modelling of Sensor-Integrated Remotely Op... | E33: ='1_Kamlesh_Panchal'!G46 | F33: ='2_Hasti_Chandarana'!G46 | G33: ='3_Nitu_Gupta'!G46 | H33: ='4_Mahendra_Kane'!G46 | I33: ='5_Parminder_Jandoo'!G46 | J33: ='6_Debasis_Dash'!G46 | K33: =E33+F33+G33+H33+I33+J33
A34: 10 | B34: H036 | C34: Student | D34: Mathematical Modeling of Motors | E34: ='1_Kamlesh_Panchal'!G48 | F34: ='2_Hasti_Chandarana'!G48 | G34: ='3_Nitu_Gupta'!G48 | H34: ='4_Mahendra_Kane'!G48 | I34: ='5_Parminder_Jandoo'!G48 | J34: ='6_Debasis_Dash'!G48 | K34: =E34+F34+G34+H34+I34+J34
A35: 10 | B35: H050 | C35: Student | D35: Mathematical Modeling of Motors | E35: ='1_Kamlesh_Panchal'!G49 | F35: ='2_Hasti_Chandarana'!G49 | G35: ='3_Nitu_Gupta'!G49 | H35: ='4_Mahendra_Kane'!G49 | I35: ='5_Parminder_Jandoo'!G49 | J35: ='6_Debasis_Dash'!G49 | K35: =E35+F35+G35+H35+I35+J35
A36: 10 | B36: H051 | C36: Student | D36: Mathematical Modeling of Motors | E36: ='1_Kamlesh_Panchal'!G50 | F36: ='2_Hasti_Chandarana'!G50 | G36: ='3_Nitu_Gupta'!G50 | H36: ='4_Mahendra_Kane'!G50 | I36: ='5_Parminder_Jandoo'!G50 | J36: ='6_Debasis_Dash'!G50 | K36: =E36+F36+G36+H36+I36+J36
A37: 10 | B37: H052 | C37: Student | D37: Mathematical Modeling of Motors | E37: ='1_Kamlesh_Panchal'!G51 | F37: ='2_Hasti_Chandarana'!G51 | G37: ='3_Nitu_Gupta'!G51 | H37: ='4_Mahendra_Kane'!G51 | I37: ='5_Parminder_Jandoo'!G51 | J37: ='6_Debasis_Dash'!G51 | K37: =E37+F37+G37+H37+I37+J37
A38: 11 | B38: H020 | C38: Student | D38: Digital Twin (DT) of Motors | E38: ='1_Kamlesh_Panchal'!G53 | F38: ='2_Hasti_Chandarana'!G53 | G38: ='3_Nitu_Gupta'!G53 | H38: ='4_Mahendra_Kane'!G53 | I38: ='5_Parminder_Jandoo'!G53 | J38: ='6_Debasis_Dash'!G53 | K38: =E38+F38+G38+H38+I38+J38
A39: 11 | B39: H096 | C39: Student | D39: Digital Twin (DT) of Motors | E39: ='1_Kamlesh_Panchal'!G54 | F39: ='2_Hasti_Chandarana'!G54 | G39: ='3_Nitu_Gupta'!G54 | H39: ='4_Mahendra_Kane'!G54 | I39: ='5_Parminder_Jandoo'!G54 | J39: ='6_Debasis_Dash'!G54 | K39: =E39+F39+G39+H39+I39+J39
A40: 12 | B40: H076 | C40: Student | D40: Mathematical Modeling for Robotic Gripper Mechanis... | E40: ='1_Kamlesh_Panchal'!G56 | F40: ='2_Hasti_Chandarana'!G56 | G40: ='3_Nitu_Gupta'!G56 | H40: ='4_Mahendra_Kane'!G56 | I40: ='5_Parminder_Jandoo'!G56 | J40: ='6_Debasis_Dash'!G56 | K40: =E40+F40+G40+H40+I40+J40
...
